{"asctime": "2020-01-03 12:00:43,623", "filename": "glogging.py", "levelno": 40, "lineno": 277, "module": "glogging", "msecs": 623.4419345855713, "message": "Exception in worker process", "name": "gunicorn.error", "pathname": "/Users/<redacted>/Envs/<redacted>-Tkf4kH1J/lib/python3.7/site-packages/gunicorn/glogging.py", "event": null, "exc_info": "Traceback (most recent call last):\n  File \"/Users/<redacted>/Envs/<redacted>-Tkf4kH1J/lib/python3.7/site-packages/gunicorn/arbiter.py\", line 583, in spawn_worker\n    worker.init_process()\n  File \"/Users/<redacted>/Envs/<redacted>-Tkf4kH1J/lib/python3.7/site-packages/gunicorn/workers/base.py\", line 129, in init_process\n    self.load_wsgi()\n  File \"/Users/<redacted>/Envs/<redacted>-Tkf4kH1J/lib/python3.7/site-packages/gunicorn/workers/base.py\", line 138, in load_wsgi\n    self.wsgi = self.app.wsgi()\n  File \"/Users/<redacted>/Envs/<redacted>-Tkf4kH1J/lib/python3.7/site-packages/gunicorn/app/base.py\", line 67, in wsgi\n    self.callable = self.load()\n  File \"/Users/<redacted>/Envs/<redacted>-Tkf4kH1J/lib/python3.7/site-packages/gunicorn/app/wsgiapp.py\", line 52, in load\n    return self.load_wsgiapp()\n  File \"/Users/<redacted>/Envs/<redacted>-Tkf4kH1J/lib/python3.7/site-packages/gunicorn/app/wsgiapp.py\", line 41, in load_wsgiapp\n    return util.import_app(self.app_uri)\n  File \"/Users/<redacted>/Envs/<redacted>-Tkf4kH1J/lib/python3.7/site-packages/gunicorn/util.py\", line 350, in import_app\n    __import__(module)\n  File \"/Users/<redacted>/library/work/gits/<redacted>/<redacted>/app.py\", line 7, in <module>\n    app = create_app(loop)\n  File \"/Users/<redacted>/library/work/gits/<redacted>/<redacted>/factory.py\", line 132, in create_app\n    loop.run_until_complete(setup_DB_pool(app, uri))\n  File \"/Users/<redacted>/.pyenv/versions/3.7.4/lib/python3.7/asyncio/base_events.py\", line 579, in run_until_complete\n    return future.result()\n  File \"/Users/<redacted>/library/work/gits/<redacted>/<redacted>/factory.py\", line 196, in setup_DB_pool\n    max_size=app.config[\"ASYNCPG_MAX_POOL_SIZE\"],\n  File \"/Users/<redacted>/Envs/<redacted>-Tkf4kH1J/lib/python3.7/site-packages/asyncpg/pool.py\", line 398, in _async__init__\n    await self._initialize()\n  File \"/Users/<redacted>/Envs/<redacted>-Tkf4kH1J/lib/python3.7/site-packages/asyncpg/pool.py\", line 426, in _initialize\n    await first_ch.connect()\n  File \"/Users/<redacted>/Envs/<redacted>-Tkf4kH1J/lib/python3.7/site-packages/asyncpg/pool.py\", line 125, in connect\n    self._con = await self._pool._get_new_connection()\n  File \"/Users/<redacted>/Envs/<redacted>-Tkf4kH1J/lib/python3.7/site-packages/asyncpg/pool.py\", line 472, in _get_new_connection\n    **self._connect_kwargs)\n  File \"/Users/<redacted>/Envs/<redacted>-Tkf4kH1J/lib/python3.7/site-packages/asyncpg/connection.py\", line 1677, in connect\n    max_cacheable_statement_size=max_cacheable_statement_size)\n  File \"/Users/<redacted>/Envs/<redacted>-Tkf4kH1J/lib/python3.7/site-packages/asyncpg/connect_utils.py\", line 662, in _connect\n    raise last_error\n  File \"/Users/<redacted>/Envs/<redacted>-Tkf4kH1J/lib/python3.7/site-packages/asyncpg/connect_utils.py\", line 654, in _connect\n    connection_class=connection_class)\n  File \"/Users/<redacted>/Envs/<redacted>-Tkf4kH1J/lib/python3.7/site-packages/asyncpg/connect_utils.py\", line 621, in _connect_addr\n    connector, timeout=timeout)\n  File \"/Users/<redacted>/.pyenv/versions/3.7.4/lib/python3.7/asyncio/tasks.py\", line 442, in wait_for\n    return fut.result()\n  File \"/Users/<redacted>/.pyenv/versions/3.7.4/lib/python3.7/asyncio/base_events.py\", line 963, in create_connection\n    ', '.join(str(exc) for exc in exceptions)))\nOSError: Multiple exceptions: [Errno 61] Connect call failed ('::1', 54321, 0, 0), [Errno 61] Connect call failed ('127.0.0.1', 54321)", "service": "<redacted>", "version": "-", "severity": "ERROR"}
